<?xml version="1.0" ?>
<!-- =================================================================================== -->
<!-- |    This document was autogenerated by xacro from allegro_hand_description_right.xacro | -->
<!-- |    EDITING THIS FILE BY HAND IS NOT RECOMMENDED                                 | -->
<!-- =================================================================================== -->
<robot name="allegro_hand_right" xmlns:xacro="http://www.ros.org/wiki/xacro">
  <!--
rosrun xacro xacro.py allegro_hand_description_right.urdf.xacro > allegro_hand_description_right.urdf
roslaunch launchers/fuerte/allegro_hand_jgui_right_virtual.launch 
-->
  <!-- ======================== BASE PARAMS ========================= -->
  <!-- ======================== FINGER PARAMS ======================== -->
  <!-- full height from joint to tip. when used,
the radius of the finger tip sphere will be subtracted
and one fixed link will be added for the tip. -->
  <!--0.0435,   0.044981-->
  <!--0.002298-->
  <!--0.002298-->
  <!-- ========================= THUMB PARAMS ========================= -->
  <!-- ========================= LIMITS ========================= -->
  <!-- ============================================================================= -->
  <!-- ============================================================================= -->
  <!-- ============================================================================= -->
  <!-- BASE -->
  <link name="base_link">
    <visual>
      <geometry>
        <mesh filename="./meshes/base_link.STL"/>
      </geometry>
      <!-- LEFT -->
      <!-- <origin rpy="${-90*DEG2RAD} 0 0" xyz="0 0 0 "/> -->
      <!-- RIGHT -->
      <origin rpy="0 0 0" xyz="0 0 0 "/>
      <material name="black">
        <color rgba="0.2 0.2 0.2 1"/>
      </material>
    </visual>
    <collision>
      <origin rpy="0 0 0" xyz="-0.009300 0 -0.0475"/>
      <geometry>
        <box size="0.0408 0.1130 0.095"/>
      </geometry>
    </collision>
  </link>
  <!-- ============================================================================= -->
  <!-- FINGERS -->
  <!-- RIGHT HAND due to which finger is number 0 -->
  <!-- for LEFT HAND switch the sign of the **offset_origin_y** and **finger_angle_r** parameters-->
  <link name="link_0_0">
    <visual>
      <geometry>
        <mesh filename="./meshes/link_0_0.STL"/>
      </geometry>
      <material name="black"/>
    </visual>
    <collision>
      <geometry>
        <box size="0.0196 0.0275 0.0164"/>
      </geometry>
      <origin rpy="0 0 0" xyz="0 0 0.0082"/>
    </collision>
  </link>
  <joint name="joint_0.0" type="revolute">
    <axis xyz="0 0 1"/>
    <limit effort="0" lower="-0.47" upper="0.47" velocity="0"/>
    <parent link="base_link"/>
    <child link="link_0_0"/>
    <origin rpy="-0.08726646255 0 0" xyz="0 0.0435 -0.001542"/>
  </joint>
  <link name="link_1_0">
    <visual>
      <geometry>
        <mesh filename="./meshes/link_1_0.STL"/>
      </geometry>
      <material name="black"/>
    </visual>
    <collision>
      <geometry>
        <box size="0.0196 0.0275 0.054"/>
      </geometry>
      <origin rpy="0 0 0" xyz="0 0 0.027"/>
    </collision>
  </link>
  <joint name="joint_1.0" type="revolute">
    <limit effort="0" lower="-0.196" upper="1.61" velocity="0"/>
    <axis xyz="0 1 0"/>
    <parent link="link_0_0"/>
    <child link="link_1_0"/>
    <origin xyz="0 0 0.0164"/>
  </joint>
  <link name="link_2_0">
    <visual>
      <geometry>
        <mesh filename="./meshes/link_2_0.STL"/>
      </geometry>
      <material name="black"/>
    </visual>
    <collision>
      <geometry>
        <box size="0.0196 0.0275 0.0384"/>
      </geometry>
      <origin rpy="0 0 0" xyz="0 0 0.0192"/>
    </collision>
  </link>
  <joint name="joint_2.0" type="revolute">
    <axis xyz="0 1 0"/>
    <limit effort="0" lower="-0.174" upper="1.709" velocity="0"/>
    <parent link="link_1_0"/>
    <child link="link_2_0"/>
    <origin xyz="0 0 0.054"/>
  </joint>
  <link name="link_3_0">
    <visual>
      <geometry>
        <mesh filename="./meshes/link_3_0.STL"/>
      </geometry>
      <material name="black"/>
    </visual>
    <collision>
      <geometry>
        <box size="0.0196 0.0275 0.0267"/>
      </geometry>
      <origin rpy="0 0 0" xyz="0 0 0.01335"/>
    </collision>
  </link>
  <joint name="joint_3.0" type="revolute">
    <axis xyz="0 1 0"/>
    <limit effort="0" lower="-0.227" upper="1.618" velocity="0"/>
    <parent link="link_2_0"/>
    <child link="link_3_0"/>
    <origin xyz="0 0 0.0384"/>
  </joint>
  <link name="link_3_0_tip">
    <visual>
      <geometry>
        <mesh filename="./meshes/link_3_0_tip.STL"/>
      </geometry>
      <material name="white">
        <color rgba=".9 .9 .9 1"/>
      </material>
    </visual>
    <collision>
      <geometry>
        <sphere radius="0.012"/>
      </geometry>
    </collision>
  </link>
  <joint name="joint_3.0_tip" type="fixed">
    <parent link="link_3_0"/>
    <child link="link_3_0_tip"/>
    <origin rpy="0 0 0" xyz="0 0 0.0267"/>
  </joint>
  <link name="link_4_0">
    <visual>
      <geometry>
        <mesh filename="./meshes/link_0_0.STL"/>
      </geometry>
      <material name="black"/>
    </visual>
    <collision>
      <geometry>
        <box size="0.0196 0.0275 0.0164"/>
      </geometry>
      <origin rpy="0 0 0" xyz="0 0 0.0082"/>
    </collision>
  </link>
  <joint name="joint_4.0" type="revolute">
    <axis xyz="0 0 1"/>
    <limit effort="0" lower="-0.47" upper="0.47" velocity="0"/>
    <parent link="base_link"/>
    <child link="link_4_0"/>
    <origin rpy="0.0 0 0" xyz="0 0 0.0007"/>
  </joint>
  <link name="link_5_0">
    <visual>
      <geometry>
        <mesh filename="./meshes/link_1_0.STL"/>
      </geometry>
      <material name="black"/>
    </visual>
    <collision>
      <geometry>
        <box size="0.0196 0.0275 0.054"/>
      </geometry>
      <origin rpy="0 0 0" xyz="0 0 0.027"/>
    </collision>
  </link>
  <joint name="joint_5.0" type="revolute">
    <limit effort="0" lower="-0.196" upper="1.61" velocity="0"/>
    <axis xyz="0 1 0"/>
    <parent link="link_4_0"/>
    <child link="link_5_0"/>
    <origin xyz="0 0 0.0164"/>
  </joint>
  <link name="link_6_0">
    <visual>
      <geometry>
        <mesh filename="./meshes/link_2_0.STL"/>
      </geometry>
      <material name="black"/>
    </visual>
    <collision>
      <geometry>
        <box size="0.0196 0.0275 0.0384"/>
      </geometry>
      <origin rpy="0 0 0" xyz="0 0 0.0192"/>
    </collision>
  </link>
  <joint name="joint_6.0" type="revolute">
    <axis xyz="0 1 0"/>
    <limit effort="0" lower="-0.174" upper="1.709" velocity="0"/>
    <parent link="link_5_0"/>
    <child link="link_6_0"/>
    <origin xyz="0 0 0.054"/>
  </joint>
  <link name="link_7_0">
    <visual>
      <geometry>
        <mesh filename="./meshes/link_3_0.STL"/>
      </geometry>
      <material name="black"/>
    </visual>
    <collision>
      <geometry>
        <box size="0.0196 0.0275 0.0267"/>
      </geometry>
      <origin rpy="0 0 0" xyz="0 0 0.01335"/>
    </collision>
  </link>
  <joint name="joint_7.0" type="revolute">
    <axis xyz="0 1 0"/>
    <limit effort="0" lower="-0.227" upper="1.618" velocity="0"/>
    <parent link="link_6_0"/>
    <child link="link_7_0"/>
    <origin xyz="0 0 0.0384"/>
  </joint>
  <link name="link_7_0_tip">
    <visual>
      <geometry>
        <mesh filename="./meshes/link_3_0_tip.STL"/>
      </geometry>
      <material name="white">
        <color rgba=".9 .9 .9 1"/>
      </material>
    </visual>
    <collision>
      <geometry>
        <sphere radius="0.012"/>
      </geometry>
    </collision>
  </link>
  <joint name="joint_7.0_tip" type="fixed">
    <parent link="link_7_0"/>
    <child link="link_7_0_tip"/>
    <origin rpy="0 0 0" xyz="0 0 0.0267"/>
  </joint>
  <link name="link_8_0">
    <visual>
      <geometry>
        <mesh filename="./meshes/link_0_0.STL"/>
      </geometry>
      <material name="black"/>
    </visual>
    <collision>
      <geometry>
        <box size="0.0196 0.0275 0.0164"/>
      </geometry>
      <origin rpy="0 0 0" xyz="0 0 0.0082"/>
    </collision>
  </link>
  <joint name="joint_8.0" type="revolute">
    <axis xyz="0 0 1"/>
    <limit effort="0" lower="-0.47" upper="0.47" velocity="0"/>
    <parent link="base_link"/>
    <child link="link_8_0"/>
    <origin rpy="0.08726646255 0 0" xyz="0 -0.0435 -0.001542"/>
  </joint>
  <link name="link_9_0">
    <visual>
      <geometry>
        <mesh filename="./meshes/link_1_0.STL"/>
      </geometry>
      <material name="black"/>
    </visual>
    <collision>
      <geometry>
        <box size="0.0196 0.0275 0.054"/>
      </geometry>
      <origin rpy="0 0 0" xyz="0 0 0.027"/>
    </collision>
  </link>
  <joint name="joint_9.0" type="revolute">
    <limit effort="0" lower="-0.196" upper="1.61" velocity="0"/>
    <axis xyz="0 1 0"/>
    <parent link="link_8_0"/>
    <child link="link_9_0"/>
    <origin xyz="0 0 0.0164"/>
  </joint>
  <link name="link_10_0">
    <visual>
      <geometry>
        <mesh filename="./meshes/link_2_0.STL"/>
      </geometry>
      <material name="black"/>
    </visual>
    <collision>
      <geometry>
        <box size="0.0196 0.0275 0.0384"/>
      </geometry>
      <origin rpy="0 0 0" xyz="0 0 0.0192"/>
    </collision>
  </link>
  <joint name="joint_10.0" type="revolute">
    <axis xyz="0 1 0"/>
    <limit effort="0" lower="-0.174" upper="1.709" velocity="0"/>
    <parent link="link_9_0"/>
    <child link="link_10_0"/>
    <origin xyz="0 0 0.054"/>
  </joint>
  <link name="link_11_0">
    <visual>
      <geometry>
        <mesh filename="./meshes/link_3_0.STL"/>
      </geometry>
      <material name="black"/>
    </visual>
    <collision>
      <geometry>
        <box size="0.0196 0.0275 0.0267"/>
      </geometry>
      <origin rpy="0 0 0" xyz="0 0 0.01335"/>
    </collision>
  </link>
  <joint name="joint_11.0" type="revolute">
    <axis xyz="0 1 0"/>
    <limit effort="0" lower="-0.227" upper="1.618" velocity="0"/>
    <parent link="link_10_0"/>
    <child link="link_11_0"/>
    <origin xyz="0 0 0.0384"/>
  </joint>
  <link name="link_11_0_tip">
    <visual>
      <geometry>
        <mesh filename="./meshes/link_3_0_tip.STL"/>
      </geometry>
      <material name="white">
        <color rgba=".9 .9 .9 1"/>
      </material>
    </visual>
    <collision>
      <geometry>
        <sphere radius="0.012"/>
      </geometry>
    </collision>
  </link>
  <joint name="joint_11.0_tip" type="fixed">
    <parent link="link_11_0"/>
    <child link="link_11_0_tip"/>
    <origin rpy="0 0 0" xyz="0 0 0.0267"/>
  </joint>
  <!-- THUMB -->
  <link name="link_12_0">
    <visual>
      <geometry>
        <!-- RIGHT -->
        <mesh filename="./meshes/link_12_0_right.STL"/>
        <!-- LEFT -->
        <!-- <mesh filename="./meshes/link_12_0_left.STL" /> -->
      </geometry>
      <material name="black">
        <color rgba=".2 .2 .2 1"/>
      </material>
    </visual>
    <collision>
      <geometry>
        <box size="0.0358 0.034 0.0455"/>
      </geometry>
      <!-- RIGHT -->
      <origin rpy="0 0 0" xyz="-0.0179 0.009 0.0145"/>
      <!-- LEFT -->
      <!-- <origin rpy="0 0 0" xyz="${-0.0358/2+0.0} ${-.018/2} ${.029/2}"/> -->
    </collision>
  </link>
  <joint name="joint_12.0" type="revolute">
    <axis xyz="-1 0 0"/>
    <limit effort="0" lower="0.263" upper="1.396" velocity="0"/>
    <parent link="base_link"/>
    <child link="link_12_0"/>
    <origin rpy="0 -1.65806278845 -1.5707963259" xyz="-0.0182 0.019333 -0.045987"/>
  </joint>
  <link name="link_13_0">
    <visual>
      <geometry>
        <mesh filename="./meshes/link_13_0.STL"/>
      </geometry>
      <material name="black">
        <color rgba=".2 .2 .2 1"/>
      </material>
    </visual>
    <collision>
      <geometry>
        <box size="0.0196 0.0275 0.0177"/>
      </geometry>
      <origin rpy="0 0 0" xyz="0 0 0.00885"/>
    </collision>
  </link>
  <joint name="joint_13.0" type="revolute">
    <axis xyz="0 0 1"/>
    <limit effort="0" lower="-0.105" upper="1.163" velocity="0"/>
    <parent link="link_12_0"/>
    <child link="link_13_0"/>
    <!-- RIGHT -->
    <origin xyz="-0.027 0.005 0.0399"/>
    <!-- LEFT -->
    <!-- <origin xyz="-0.027 -0.005 0.0399"/> -->
  </joint>
  <link name="link_14_0">
    <visual>
      <geometry>
        <mesh filename="./meshes/link_14_0.STL"/>
      </geometry>
      <material name="black">
		  	</material>
    </visual>
    <collision>
      <geometry>
        <box size="0.0196 0.0275 0.0514"/>
      </geometry>
      <origin rpy="0 0 0" xyz="0 0 0.0257"/>
    </collision>
  </link>
  <joint name="joint_14.0" type="revolute">
    <axis xyz="0 1 0"/>
    <limit effort="0" lower="-0.189" upper="1.644" velocity="0"/>
    <parent link="link_13_0"/>
    <child link="link_14_0"/>
    <origin xyz="0 0 0.0177"/>
  </joint>
  <link name="link_15_0">
    <visual>
      <geometry>
        <mesh filename="./meshes/link_15_0.STL"/>
      </geometry>
      <material name="black">
    	</material>
    </visual>
    <collision>
      <geometry>
        <box size="0.0196 0.0275 0.0423"/>
      </geometry>
      <origin rpy="0 0 0" xyz="0 0 0.02115"/>
    </collision>
  </link>
  <joint name="joint_15.0" type="revolute">
    <axis xyz="0 1 0"/>
    <limit effort="0" lower="-0.162" upper="1.719" velocity="0"/>
    <parent link="link_14_0"/>
    <child link="link_15_0"/>
    <origin xyz="0 0 0.0514"/>
  </joint>
  <link name="link_15_0_tip">
    <visual>
      <geometry>
        <mesh filename="./meshes/link_15_0_tip.STL"/>
      </geometry>
      <material name="white">
        <color rgba=".9 .9 .9 1"/>
      </material>
    </visual>
    <collision>
      <geometry>
        <sphere radius="0.012"/>
      </geometry>
      <origin rpy="0 0 0" xyz="0 0 0"/>
    </collision>
  </link>
  <joint name="joint_15.0_tip" type="fixed">
    <parent link="link_15_0"/>
    <child link="link_15_0_tip"/>
    <origin rpy="0 0 0" xyz="0 0 0.0423"/>
    <!--0.0267000000000005-->
  </joint>
  <!--
<xacro:thumb_left 
	finger_num=			"3" 
	offset_origin_x=	"-0.0182"	
	offset_origin_y=	"-0.019333" 
	offset_origin_z=	"-0.045987" 
	
	
	finger_angle_r=		"${90*DEG2RAD}"
	finger_angle_p=		"-${95*DEG2RAD}"	
	finger_angle_y=		"${90*DEG2RAD}"
/>
-->
  <!-- ============================================================================= -->
  <!-- ============================================================================= -->
  <!-- ============================================================================= -->
  <!-- THUMB MACRO -->
  <!-- END THUMB MACRO -->
  <!-- THREE FINGER MACRO -->
  <!-- [[END]] THREE FINGER MACRO -->
</robot>
